Workbook

Sheet Corrections
A1: 1900–2000 Hempstead Tpke — Corrected Feasibility Model
A2: Retail (former Home Depot / Modell's) → indoor-agriculture white-box landlord, East Meadow, NY 11554. Rebuilt from the 2021 capstone model using the master-builder skill.
A4: # | B4: What was wrong in the original model | C4: Correction applied here
A5: 1 | B5: Two conflicting NOI figures; operating tab added OpEx to income (NOI ≈ rent + opex ≈ $8.4M) instead of subtracting it. | C5: Single NOI = EGI − non-reimbursable costs, used everywhere (DSCR, exit, returns).
A6: 2 | B6: ~$1.05M of itemized soft costs (architect, MEP, energy/ag consultants, expeditor, T&B) never flowed into Sources & Uses. | C6: Full $1,072,500 soft-cost schedule restored and footed into the development budget.
A7: 3 | B7: Wind = $5.8M (33% of hard cost) for ~334 MWh/yr (~2% of on-site energy) — ~38× worse $/kWh than solar. | C7: Wind removed in base case (VE move); toggle in Assumptions!B15 to switch it back on.
A8: 4 | B8: Transfer/closing modeled at 10% of purchase (~$1.57M) — high for NY commercial. | C8: Transfer/closing set to a 4% lever (Assumptions!B5); adjust to your title/tax quote.
A9: 5 | B9: Zero vacancy modeled forever for an unproven, single-class tenant base. | C9: Vacancy set to 10% base (lever); stress grid runs 5–20%.
A10: 6 | B10: Depreciation (non-cash) sat inside OpEx, suppressing NOI. Insurance labeled 5% but computed ~0.4%. Staff 25 vs 10 in cells. | C10: Non-cash items removed from NOI; modeled NNN with clean non-reimbursable landlord costs.
A11: 7 | B11: Per-tenant power printed as '$203,563/day'; building electric as '$1.0M/mo' — order-of-magnitude unit errors. | C11: Modeled NNN: tenants carry grow-power directly. Tenant power economics flagged as the binding risk (see note).
A12: 8 | B12: Exit at a 6.14% cap with no comparable market for indoor-ag real estate; demand assumed 5 solvent tenants. | C12: Exit cap kept as a lever; sensitivity stresses 5.5–7.5%. Demand risk documented below.
A14: The binding risk (why the business, not the building, is the question):
A15: The building conversion pencils once wind is cut and transfer normalized (see Returns). The real risk is tenant viability: indoor grow-lighting for 200,000 sf runs on the order of ~20M+ kWh/yr — at ~$0.10/kWh that is ~$2M+/yr of power the TENANT must cover from thin-margin leafy-green revenue. That unit-economics gap is exactly what bankrupted the operators named as target tenants (AeroFarms Ch.11 2023; Bowery ceased ops 2024; Plenty Ch.11 2025; AppHarvest 2023). De-risk demand before capital: secure anchor/off-take leases, then phase-build one PFAL to prove the tenant's real power bill.

Sheet Assumptions
A1: Assumptions & Levers
A2: Blue = input · Yellow = key assumption to pressure-test · Black = formula
A4: ACQUISITION
A5: Purchase price (both parcels) | B5: 15744700 | C5: 2000 Tpke $12.74M + 1980 Tpke $3.0M
A6: Transfer & closing (% of price) | B6: 0.04 | C6: Original used 10% — high for NY commercial
A7: Legal & due diligence | B7: 15000
A8: Survey & title | B8: 20000
A10: HARD COSTS
A11: Re-roof to collection plane | B11: 25000
A12: Demolition & grading | B12: 50000
A13: Sitework | B13: 25000
A14: Solar array (roof + carport) | B14: 8249918 | C14: Flag: $330/panel likely light 2–3× vs installed commercial
A15: Wind turbines (gross) | B15: 5805000 | C15: 1,161 vertical turbines
A16: Wind INCLUDE? (1=yes, 0=no) | B16: 0 | C16: VE move: 0 removes wind (33% of hard cost, ~2% of energy)
A17: Battery storage (7 units) | B17: 105000
A18: Rainwater tank & system | B18: 780000
A19: HVAC / pumping / filtration | B19: 50000
A20: Electrical power upgrade | B20: 100000
A21: Electrical lighting (common) | B21: 15000
A22: Chiller | B22: 200000
A23: Loading dock | B23: 40000
A24: Architectural upgrades | B24: 75000
A25: Produce market fit-out | B25: 325000
A26: Hard-cost contingency (%) | B26: 0.15
A28: SOFT COSTS
A29: Architect | B29: 350000
A30: Structural engineer | B30: 100000
A31: Mechanical engineer | B31: 100000
A32: Energy consultant | B32: 75000
A33: Agriculture consultant | B33: 125000
A34: DOB expeditor | B34: 75000
A35: Testing & balancing | B35: 150000
A36: Design contingency (%) | B36: 0.1
A38: OTHER DEVELOPMENT
A39: Developer contingency (%) | B39: 0.05
A40: Construction period (years) | B40: 1
A42: FINANCING
A43: Loan-to-cost (%) | B43: 0.6
A44: Interest rate (%) | B44: 0.045
A45: Amortization (years) | B45: 25
...

Sheet Dev Budget
A1: Development Budget — Sources & Uses
A3: USES OF CAPITAL
A4: Acquisition
A5: Purchase price | B5: =Assumptions!B5 -> 15744700
A6: Transfer & closing | B6: =Assumptions!B5*Assumptions!B6 -> 629788
A7: Legal & due diligence | B7: =Assumptions!B7 -> 15000
A8: Survey & title | B8: =Assumptions!B8 -> 20000
A9: Subtotal — Acquisition | B9: =SUM(B5:B8) -> 16409488
A11: Hard Costs
A12: Re-roof to collection plane | B12: =Assumptions!B11 -> 25000
A13: Demolition & grading | B13: =Assumptions!B12 -> 50000
A14: Sitework | B14: =Assumptions!B13 -> 25000
A15: Solar array | B15: =Assumptions!B14 -> 8249918
A16: Wind turbines (toggle) | B16: =Assumptions!B15*Assumptions!B16 -> 0 | C16: 0 when wind switched off
A17: Battery storage | B17: =Assumptions!B17 -> 105000
A18: Rainwater tank & system | B18: =Assumptions!B18 -> 780000
A19: HVAC / pumping / filtration | B19: =Assumptions!B19 -> 50000
A20: Electrical power upgrade | B20: =Assumptions!B20 -> 100000
A21: Electrical lighting (common) | B21: =Assumptions!B21 -> 15000
A22: Chiller | B22: =Assumptions!B22 -> 200000
A23: Loading dock | B23: =Assumptions!B23 -> 40000
A24: Architectural upgrades | B24: =Assumptions!B24 -> 75000
A25: Produce market fit-out | B25: =Assumptions!B25 -> 325000
A26: Hard subtotal (pre-contingency) | B26: =SUM(B12:B25) -> 10039918
A27: Hard-cost contingency | B27: =B26*Assumptions!B26 -> 1505987.7
A28: Total Hard Costs | B28: =B26+B27 -> 11545906
A30: Soft Costs
A31: Architect | B31: =Assumptions!B29 -> 350000
A32: Structural engineer | B32: =Assumptions!B30 -> 100000
A33: Mechanical engineer | B33: =Assumptions!B31 -> 100000
A34: Energy consultant | B34: =Assumptions!B32 -> 75000
A35: Agriculture consultant | B35: =Assumptions!B33 -> 125000
A36: DOB expeditor | B36: =Assumptions!B34 -> 75000
A37: Testing & balancing | B37: =Assumptions!B35 -> 150000
A38: Soft subtotal | B38: =SUM(B31:B37) -> 975000
A39: Design contingency | B39: =B38*Assumptions!B36 -> 97500
A40: Total Soft Costs | B40: =B38+B39 -> 1072500 | C40: Restored: original dropped ~$1.05M of this from S&U
A42: Other Development
A43: Developer contingency | B43: =(B28+B40)*Assumptions!B39 -> 630920.29
A44: Costs excl. financing carry | B44: =B9+B28+B40+B43 -> 29658814
...

Sheet Pro Forma
A1: Operating Pro Forma — NNN white-box landlord
A2: Year 0 acquisition · Year 1 construction · Years 2–11 operations · sale end of Year 11
B4: Year 0 | C4: Year 1 | D4: Year 2 | E4: Year 3 | F4: Year 4 | G4: Year 5 | H4: Year 6 | I4: Year 7 | J4: Year 8 | K4: Year 9 | L4: Year 10 | M4: Year 11
A5: Potential base rent | B5: 0 | C5: 0 | D5: =Assumptions!B48*Assumptions!B49*12 -> 3600000 | E5: =D5*(1+Assumptions!B50) -> 3654000 | F5: =E5*(1+Assumptions!B50) -> 3708810 | G5: =F5*(1+Assumptions!B50) -> 3764442.1 | H5: =G5*(1+Assumptions!B50) -> 3820908.8 | I5: =H5*(1+Assumptions!B50) -> 3878222.4 | J5: =I5*(1+Assumptions!B50) -> 3936395.8 | K5: =J5*(1+Assumptions!B50) -> 3995441.7 | L5: =K5*(1+Assumptions!B50) -> 4055373.3 | M5: =L5*(1+Assumptions!B50) -> 4116203.9
A6: Less: vacancy & credit loss | B6: 0 | C6: 0 | D6: =-D5*Assumptions!B51 -> -360000 | E6: =-E5*Assumptions!B51 -> -365400 | F6: =-F5*Assumptions!B51 -> -370881 | G6: =-G5*Assumptions!B51 -> -376444.22 | H6: =-H5*Assumptions!B51 -> -382090.88 | I6: =-I5*Assumptions!B51 -> -387822.24 | J6: =-J5*Assumptions!B51 -> -393639.58 | K6: =-K5*Assumptions!B51 -> -399544.17 | L6: =-L5*Assumptions!B51 -> -405537.33 | M6: =-M5*Assumptions!B51 -> -411620.39
A7: Effective Gross Income (EGI) | B7: =B5+B6 -> 0 | C7: =C5+C6 -> 0 | D7: =D5+D6 -> 3240000 | E7: =E5+E6 -> 3288600 | F7: =F5+F6 -> 3337929 | G7: =G5+G6 -> 3387997.9 | H7: =H5+H6 -> 3438817.9 | I7: =I5+I6 -> 3490400.2 | ... M7: =M5+M6 -> 3704583.5
A8: Less: management fee | B8: 0 | C8: 0 | D8: =-D7*Assumptions!B52 -> -97200 | E8: =-E7*Assumptions!B52 -> -98658 | F8: =-F7*Assumptions!B52 -> -100137.87 | G8: =-G7*Assumptions!B52 -> -101639.94 | H8: =-H7*Assumptions!B52 -> -103164.54 | I8: =-I7*Assumptions!B52 -> -104712.01 | J8: =-J7*Assumptions!B52 -> -106282.69 | K8: =-K7*Assumptions!B52 -> -107876.93 | L8: =-L7*Assumptions!B52 -> -109495.08 | M8: =-M7*Assumptions!B52 -> -111137.51
A9: Less: reserves | B9: 0 | C9: 0 | D9: =-Assumptions!B48*Assumptions!B53 -> -50000 | E9: =-Assumptions!B48*Assumptions!B53 -> -50000 | F9: =-Assumptions!B48*Assumptions!B53 -> -50000 | G9: =-Assumptions!B48*Assumptions!B53 -> -50000 | H9: =-Assumptions!B48*Assumptions!B53 -> -50000 | I9: =-Assumptions!B48*Assumptions!B53 -> -50000 | J9: =-Assumptions!B48*Assumptions!B53 -> -50000 | K9: =-Assumptions!B48*Assumptions!B53 -> -50000 | L9: =-Assumptions!B48*Assumptions!B53 -> -50000 | M9: =-Assumptions!B48*Assumptions!B53 -> -50000
A10: Less: shell insurance | B10: 0 | C10: 0 | D10: =-Assumptions!B48*Assumptions!B54 -> -70000 | E10: =-Assumptions!B48*Assumptions!B54 -> -70000 | F10: =-Assumptions!B48*Assumptions!B54 -> -70000 | G10: =-Assumptions!B48*Assumptions!B54 -> -70000 | H10: =-Assumptions!B48*Assumptions!B54 -> -70000 | I10: =-Assumptions!B48*Assumptions!B54 -> -70000 | J10: =-Assumptions!B48*Assumptions!B54 -> -70000 | K10: =-Assumptions!B48*Assumptions!B54 -> -70000 | L10: =-Assumptions!B48*Assumptions!B54 -> -70000 | M10: =-Assumptions!B48*Assumptions!B54 -> -70000
A11: Net Operating Income (NOI) | B11: =B7+B8+B9+B10 -> 0 | C11: =C7+C8+C9+C10 -> 0 | D11: =D7+D8+D9+D10 -> 3022800 | E11: =E7+E8+E9+E10 -> 3069942 | F11: =F7+F8+F9+F10 -> 3117791.1 | G11: =G7+G8+G9+G10 -> 3166358 | H11: =H7+H8+H9+H10 -> 3215653.4 | I11: =I7+I8+I9+I10 -> 3265688.2 | ... M11: =M7+M8+M9+M10 -> 3473446

Sheet Returns
A1: Returns, Debt & Sensitivity
A3: KEY METRICS
A4: Total Development Cost | B4: ='Dev Budget'!B49 -> 30059208
A5: Loan | B5: ='Dev Budget'!B50 -> 17795288
A6: Equity | B6: ='Dev Budget'!B51 -> 12263920
A7: Stabilized NOI (Year 2) | B7: ='Pro Forma'!D11 -> 3022800
A8: Yield on Cost | B8: =B7/B4 -> 0.10056153 | C8: Compare to exit cap
A9: Exit cap rate | B9: =Assumptions!B57 -> 0.0614
A10: Development spread | B10: =B8-B9 -> 0.039161532 | C10: >150–250 bps is the compensation for development risk
A12: Annual debt service (PMT) | B12: =PMT(Assumptions!B44,Assumptions!B45,-B5) -> 1200097
A13: DSCR (stabilized) | B13: =B7/B12 -> 2.5187965
A14: Loan balance after 10 yrs | B14: =B5*(1+Assumptions!B44)^10-B12*((1+Assumptions!B44)^10-1)/Assumptions!B44 -> 12888496
A15: Sale price (Yr11 NOI ÷ exit cap) | B15: ='Pro Forma'!M11/Assumptions!B57 -> 56570782
A16: Net sale proceeds | B16: =B15*(1-Assumptions!B58) -> 55439366
A18: CASH FLOW & RETURNS
B19: Year 0 | C19: Year 1 | D19: Year 2 | E19: Year 3 | F19: Year 4 | G19: Year 5 | H19: Year 6 | I19: Year 7 | J19: Year 8 | K19: Year 9 | L19: Year 10 | M19: Year 11
A20: Unlevered cash flow | B20: =-'Dev Budget'!B9 -> -16409488 | C20: =-('Dev Budget'!B28+'Dev Budget'!B40+'Dev Budget'!B43+'Dev Budget'!B48) -> -13649720 | D20: ='Pro Forma'!D11 -> 3022800 | E20: ='Pro Forma'!E11 -> 3069942 | F20: ='Pro Forma'!F11 -> 3117791.1 | G20: ='Pro Forma'!G11 -> 3166358 | H20: ='Pro Forma'!H11 -> 3215653.4 | I20: ='Pro Forma'!I11 -> 3265688.2 | J20: ='Pro Forma'!J11 -> 3316473.5 | K20: ='Pro Forma'!K11 -> 3368020.6 | L20: ='Pro Forma'!L11 -> 3420340.9 | M20: ='Pro Forma'!M11+B16 -> 58912812
A21: Unlevered IRR | B21: =IRR(B20:M20) -> 0.13651817
A23: Levered cash flow (equity) | B23: =-('Dev Budget'!B9-B5*'Dev Budget'!B9/B4) -> -6694941.6 | C23: =-(('Dev Budget'!B28+'Dev Budget'!B40+'Dev Budget'!B43+'Dev Budget'!B48)-B5*(B4-'Dev Budget'!B9)/B4) -> -5568978 | D23: ='Pro Forma'!D11-B12 -> 1822703 | E23: ='Pro Forma'!E11-B12 -> 1869845 | F23: ='Pro Forma'!F11-B12 -> 1917694.2 | G23: ='Pro Forma'!G11-B12 -> 1966261 | H23: ='Pro Forma'!H11-B12 -> 2015556.4 | I23: ='Pro Forma'!I11-B12 -> 2065591.2 | J23: ='Pro Forma'!J11-B12 -> 2116376.5 | K23: ='Pro Forma'!K11-B12 -> 2167923.6 | L23: ='Pro Forma'!L11-B12 -> 2220243.9 | M23: ='Pro Forma'!M11-B12+B16-B14 -> 44824219
A24: Levered IRR | B24: =IRR(B23:M23) -> 0.21759359
A25: Equity multiple (levered) | B25: =(SUM(D23:M23))/-SUM(B23:C23) -> 5.1359122
A27: Note: NNN structure — tenants carry power/water directly. Tenant grow-power economics are the binding risk (see Corrections).
A29: SENSITIVITY — Levered IRR
A30: Static grid computed at delivery from the base inputs — re-run if you change assumptions.
A31: Vacancy ↓ / Exit cap → | B31: 0.055 | C31: 0.06 | D31: 0.0614 | E31: 0.065 | F31: 0.07 | G31: 0.075
A32: 0.05 | B32: 0.24238382 | C32: 0.23434071 | D32: 0.23222699 | E32: 0.22703841 | F32: 0.22035961 | G32: 0.21421225
A33: 0.1 | B33: 0.22874541 | C33: 0.22047243 | D33: 0.21829515 | E33: 0.21294463 | F33: 0.20604425 | G33: 0.19967891
A34: 0.15 | B34: 0.21448773 | C34: 0.20596087 | D34: 0.20371314 | E34: 0.19818265 | F34: 0.19103496 | G34: 0.18442505
A35: 0.2 | B35: 0.19950824 | C35: 0.19069702 | D35: 0.1883701 | E35: 0.1826367 | F35: 0.17520873 | G35: 0.16832003
A37: Base case (10% vacancy, 6.14% exit) shown in the cash-flow block above.
